ERROR:root:20:24:58.047068: ord() expected string of length 1, but int found
ERROR:app:Exception on /users [GET]
Traceback (most recent call last):
  File "/home/gbenats/Development/API/weak_jotapi/weakJWTlib/auth_utils.py", line 45, in wrapper
    decoded = jwt.decode(authHeader.split('Bearer ')[1].strip(), jwt_key, algorithms=current_app.config['SUPPORTED_ALGORITHMS'])
  File "/home/gbenats/Development/API/weak_jotapi/weakJWTlib/venv/lib/python3.8/site-packages/jwt/api_jwt.py", line 91, in decode
    decoded = super(PyJWT, self).decode(
  File "/home/gbenats/Development/API/weak_jotapi/weakJWTlib/venv/lib/python3.8/site-packages/jwt/api_jws.py", line 154, in decode
    self._verify_signature(payload, signing_input, header, signature,
  File "/home/gbenats/Development/API/weak_jotapi/weakJWTlib/venv/lib/python3.8/site-packages/jwt/api_jws.py", line 221, in _verify_signature
    if not alg_obj.verify(signing_input, key, signature):
  File "/home/gbenats/Development/API/weak_jotapi/weakJWTlib/venv/lib/python3.8/site-packages/jwt/algorithms.py", line 178, in verify
    return constant_time_compare(sig, self.sign(msg, key))
  File "/home/gbenats/Development/API/weak_jotapi/weakJWTlib/venv/lib/python3.8/site-packages/jwt/compat.py", line 45, in constant_time_compare
    result |= ord(x) ^ ord(y)
TypeError: ord() expected string of length 1, but int found

During handling of the above exception, another exception occurred:

Traceback (most recent call last):
  File "/home/gbenats/Development/API/weak_jotapi/weakJWTlib/venv/lib/python3.8/site-packages/flask/app.py", line 2447, in wsgi_app
    response = self.full_dispatch_request()
  File "/home/gbenats/Development/API/weak_jotapi/weakJWTlib/venv/lib/python3.8/site-packages/flask/app.py", line 1952, in full_dispatch_request
    rv = self.handle_user_exception(e)
  File "/home/gbenats/Development/API/weak_jotapi/weakJWTlib/venv/lib/python3.8/site-packages/flask/app.py", line 1821, in handle_user_exception
    reraise(exc_type, exc_value, tb)
  File "/home/gbenats/Development/API/weak_jotapi/weakJWTlib/venv/lib/python3.8/site-packages/flask/_compat.py", line 39, in reraise
    raise value
  File "/home/gbenats/Development/API/weak_jotapi/weakJWTlib/venv/lib/python3.8/site-packages/flask/app.py", line 1950, in full_dispatch_request
    rv = self.dispatch_request()
  File "/home/gbenats/Development/API/weak_jotapi/weakJWTlib/venv/lib/python3.8/site-packages/flask/app.py", line 1936, in dispatch_request
    return self.view_functions[rule.endpoint](**req.view_args)
  File "/home/gbenats/Development/API/weak_jotapi/weakJWTlib/auth_utils.py", line 72, in wrapper
    raise InternalServerError(exception)
errors.InternalServerError: An internal error occured, please check your parameters.
ERROR:root:20:25:55.378117: Signature verification failed
ERROR:app:Exception on /users [GET]
Traceback (most recent call last):
  File "/home/gbenats/Development/API/weak_jotapi/weakJWTlib/auth_utils.py", line 45, in wrapper
    decoded = jwt.decode(authHeader.split('Bearer ')[1].strip(), jwt_key, algorithms=current_app.config['SUPPORTED_ALGORITHMS'])
  File "/home/gbenats/Development/API/weak_jotapi/weakJWTlib/venv/lib/python3.8/site-packages/jwt/api_jwt.py", line 91, in decode
    decoded = super(PyJWT, self).decode(
  File "/home/gbenats/Development/API/weak_jotapi/weakJWTlib/venv/lib/python3.8/site-packages/jwt/api_jws.py", line 154, in decode
    self._verify_signature(payload, signing_input, header, signature,
  File "/home/gbenats/Development/API/weak_jotapi/weakJWTlib/venv/lib/python3.8/site-packages/jwt/api_jws.py", line 222, in _verify_signature
    raise InvalidSignatureError('Signature verification failed')
jwt.exceptions.InvalidSignatureError: Signature verification failed

During handling of the above exception, another exception occurred:

Traceback (most recent call last):
  File "/home/gbenats/Development/API/weak_jotapi/weakJWTlib/venv/lib/python3.8/site-packages/flask/app.py", line 2447, in wsgi_app
    response = self.full_dispatch_request()
  File "/home/gbenats/Development/API/weak_jotapi/weakJWTlib/venv/lib/python3.8/site-packages/flask/app.py", line 1952, in full_dispatch_request
    rv = self.handle_user_exception(e)
  File "/home/gbenats/Development/API/weak_jotapi/weakJWTlib/venv/lib/python3.8/site-packages/flask/app.py", line 1821, in handle_user_exception
    reraise(exc_type, exc_value, tb)
  File "/home/gbenats/Development/API/weak_jotapi/weakJWTlib/venv/lib/python3.8/site-packages/flask/_compat.py", line 39, in reraise
    raise value
  File "/home/gbenats/Development/API/weak_jotapi/weakJWTlib/venv/lib/python3.8/site-packages/flask/app.py", line 1950, in full_dispatch_request
    rv = self.dispatch_request()
  File "/home/gbenats/Development/API/weak_jotapi/weakJWTlib/venv/lib/python3.8/site-packages/flask/app.py", line 1936, in dispatch_request
    return self.view_functions[rule.endpoint](**req.view_args)
  File "/home/gbenats/Development/API/weak_jotapi/weakJWTlib/auth_utils.py", line 66, in wrapper
    raise InvalidSignatureError(error)
errors.InvalidSignatureError: The JWT token signature is not using authorized authentication methods for this user.
ERROR:root:20:26:54.861284: Signature verification failed
ERROR:app:Exception on /users [GET]
Traceback (most recent call last):
  File "/home/gbenats/Development/API/weak_jotapi/weakJWTlib/auth_utils.py", line 45, in wrapper
    decoded = jwt.decode(authHeader.split('Bearer ')[1].strip(), jwt_key, algorithms=current_app.config['SUPPORTED_ALGORITHMS'])
  File "/home/gbenats/Development/API/weak_jotapi/weakJWTlib/venv/lib/python3.8/site-packages/jwt/api_jwt.py", line 91, in decode
    decoded = super(PyJWT, self).decode(
  File "/home/gbenats/Development/API/weak_jotapi/weakJWTlib/venv/lib/python3.8/site-packages/jwt/api_jws.py", line 154, in decode
    self._verify_signature(payload, signing_input, header, signature,
  File "/home/gbenats/Development/API/weak_jotapi/weakJWTlib/venv/lib/python3.8/site-packages/jwt/api_jws.py", line 225, in _verify_signature
    raise InvalidSignatureError('Signature verification failed')
jwt.exceptions.InvalidSignatureError: Signature verification failed

During handling of the above exception, another exception occurred:

Traceback (most recent call last):
  File "/home/gbenats/Development/API/weak_jotapi/weakJWTlib/venv/lib/python3.8/site-packages/flask/app.py", line 2447, in wsgi_app
    response = self.full_dispatch_request()
  File "/home/gbenats/Development/API/weak_jotapi/weakJWTlib/venv/lib/python3.8/site-packages/flask/app.py", line 1952, in full_dispatch_request
    rv = self.handle_user_exception(e)
  File "/home/gbenats/Development/API/weak_jotapi/weakJWTlib/venv/lib/python3.8/site-packages/flask/app.py", line 1821, in handle_user_exception
    reraise(exc_type, exc_value, tb)
  File "/home/gbenats/Development/API/weak_jotapi/weakJWTlib/venv/lib/python3.8/site-packages/flask/_compat.py", line 39, in reraise
    raise value
  File "/home/gbenats/Development/API/weak_jotapi/weakJWTlib/venv/lib/python3.8/site-packages/flask/app.py", line 1950, in full_dispatch_request
    rv = self.dispatch_request()
  File "/home/gbenats/Development/API/weak_jotapi/weakJWTlib/venv/lib/python3.8/site-packages/flask/app.py", line 1936, in dispatch_request
    return self.view_functions[rule.endpoint](**req.view_args)
  File "/home/gbenats/Development/API/weak_jotapi/weakJWTlib/auth_utils.py", line 66, in wrapper
    raise InvalidSignatureError(error)
errors.InvalidSignatureError: The JWT token signature is not using authorized authentication methods for this user.
ERROR:root:20:28:53.509841: Signature verification failed
ERROR:app:Exception on /users [GET]
Traceback (most recent call last):
  File "/home/gbenats/Development/API/weak_jotapi/weakJWTlib/auth_utils.py", line 45, in wrapper
    decoded = jwt.decode(authHeader.split('Bearer ')[1].strip(), jwt_key, algorithms=current_app.config['SUPPORTED_ALGORITHMS'])
  File "/home/gbenats/Development/API/weak_jotapi/weakJWTlib/venv/lib/python3.8/site-packages/jwt/api_jwt.py", line 91, in decode
    decoded = super(PyJWT, self).decode(
  File "/home/gbenats/Development/API/weak_jotapi/weakJWTlib/venv/lib/python3.8/site-packages/jwt/api_jws.py", line 154, in decode
    self._verify_signature(payload, signing_input, header, signature,
  File "/home/gbenats/Development/API/weak_jotapi/weakJWTlib/venv/lib/python3.8/site-packages/jwt/api_jws.py", line 225, in _verify_signature
    raise InvalidSignatureError('Signature verification failed')
jwt.exceptions.InvalidSignatureError: Signature verification failed

During handling of the above exception, another exception occurred:

Traceback (most recent call last):
  File "/home/gbenats/Development/API/weak_jotapi/weakJWTlib/venv/lib/python3.8/site-packages/flask/app.py", line 2447, in wsgi_app
    response = self.full_dispatch_request()
  File "/home/gbenats/Development/API/weak_jotapi/weakJWTlib/venv/lib/python3.8/site-packages/flask/app.py", line 1952, in full_dispatch_request
    rv = self.handle_user_exception(e)
  File "/home/gbenats/Development/API/weak_jotapi/weakJWTlib/venv/lib/python3.8/site-packages/flask/app.py", line 1821, in handle_user_exception
    reraise(exc_type, exc_value, tb)
  File "/home/gbenats/Development/API/weak_jotapi/weakJWTlib/venv/lib/python3.8/site-packages/flask/_compat.py", line 39, in reraise
    raise value
  File "/home/gbenats/Development/API/weak_jotapi/weakJWTlib/venv/lib/python3.8/site-packages/flask/app.py", line 1950, in full_dispatch_request
    rv = self.dispatch_request()
  File "/home/gbenats/Development/API/weak_jotapi/weakJWTlib/venv/lib/python3.8/site-packages/flask/app.py", line 1936, in dispatch_request
    return self.view_functions[rule.endpoint](**req.view_args)
  File "/home/gbenats/Development/API/weak_jotapi/weakJWTlib/auth_utils.py", line 66, in wrapper
    raise InvalidSignatureError(error)
errors.InvalidSignatureError: The JWT token signature is not using authorized authentication methods for this user.
